Workbook

Sheet xx
Q2: Project No.
Q3: Document No.
Q4: Issued for
Q5: Prepared By
B6: Date | Q6: Checked By
B7: Rev. | Q7: Approved By
B8: Step | C8: Process Step | D8: Material | E8: Molecular weight | F8: Kmoles | H8: Mass in kg | I8: Mass out Kg | J8: Accumn kg | L8: Sp gr | M8: Volume in L | N8: Volume out L | O8: Accumn. L | P8: Time | R8: Pressure | S8: Scrubber and vacuum | T8: Temp. 0C | U8: Utility Brine/CW/CHW/steam/ Nitrogen blanketing | V8: Remarks
B9: 6.3 KL GLR Pre Mixer (PM-1402 / PM-XXXX) Reactor Qty : 2 Nos | P9: Min | Q9: Hrs | X9: Equipment Name | Y9: PM - 1402 / PM - XXXX | AB9: HE Primary | AC9: PM - 1402 / PM - XXXX
B10: 1 | C10: Hexane Receive in Reacter By Pump From Hexane Day Tank (DT-1402 / DT-XXXX) | D10: HEXANE | E10: NA | H10: 1200 | J10: =H10-I10 -> 1200 | L10: 0.65 | M10: =H10/L10 -> 1846.1538 | O10: =M10-N10 -> 1846.1538 | P10: 60 | Q10: =P10/60 -> 1 | R10: - | S10: - | T10: 20-25 deg C | U10: CHW | X10: Process Step | Y10: Reaction | AB10: Utility | AC10: CW
B11: 2 | C11: Charge MPBD under vacuum through drum | D11: MPBD | E11: NA | H11: 875 | J11: =J10+H11-I11 -> 2075 | L11: 1.2 | M11: =H11/L11 -> 729.16667 | O11: =O10+M11-N11 -> 2575.3205 | P11: 60 | Q11: =P11/60 -> 1 | R11: Vacuum | S11: Vacuum | T11: 20-25 deg C | U11: CW/CHW | X11: Batch Cycle Time | Y11: =Q15+SUM(Q22:Q28) -> 16.5 | AB11: Area (m2) | AC11: 18
B12: 3 | C12: Charge IN-1 under vacuum by drum | D12: IN-1 | E12: NA | H12: 1225 | J12: =J11+H12-I12 -> 3300 | L12: 1.44 | M12: =H12/L12 -> 850.69444 | O12: =O11+M12-N12 -> 3426.015 | P12: 60 | Q12: =P12/60 -> 1 | R12: Vacuum | S12: Vacuum | T12: 20-25 deg C | U12: CW/CHW | X12: MOC | Y12: MSGL | AB12: MOC | AC12: Graphite
B13: 4 | C13: Apply brine and cool down the temp to 8 deg C | J13: =J12+H13-I13 -> 3300 | O13: =O12+M13-N13 -> 3426.015 | P13: 60 | Q13: =P13/60 -> 1 | R13: ATM | T13: 8 deg C | U13: CHW/CHB | X13: Nature | Y13: Acidic | AB13: Type | AC13: Cylindrical
B14: 5 | C14: Mixing for 1 hr | J14: =J13+H14-I14 -> 3300 | O14: =O13+M14-N14 -> 3426.015 | P14: 60 | Q14: =P14/60 -> 1 | R14: ATM | T14: 8 deg C | U14: CHW/CHB | X14: Reactor Volume | Y14: 6.3 KL
B15: Total | D15: - | E15: - | F15: - | H15: =SUM(H10:H14) -> 3300 | I15: =SUM(I10:I14) -> 0 | J15: =H15-I15 -> 3300 | L15: - | M15: =SUM(M10:M14) -> 3426.015 | N15: =SUM(N10:N14) -> 0 | O15: =M15-N15 -> 3426.015 | P15: =SUM(P10:P14) -> 300 | Q15: =SUM(Q10:Q14) -> 5 | R15: - | S15: - | T15: - | U15: - | X15: Pressure | Y15: FV TO ATM | AB15: HE Secondary | AC15: PM - 1402 / PM - XXXX
B16: 3 KL SSR Cyanide Reactor (R-1402) Reactor Qty : 1 Nos | X16: Temperature | Y16: 8 TO 35 Deg. C max. | AB16: Utility | AC16: CHW
B17: 1 | C17: Charge 1200 kg water | D17: WATER | E17: 18 | H17: 1200 | J17: =J16+H17-I17 -> 1200 | L17: 1 | M17: =H17/L17 -> 1200 | O17: =M17-N17 -> 1200 | P17: 60 | Q17: =P17/60 -> 1 | R17: ATM | T17: 25-30 deg C | U17: CW / CHW | X17: RPM | Y17: 95 | AB17: Area (m2) | AC17: 10
B18: 2 | C18: Charge 250kg Sodium cyanide through manhole under vacuum and against air direaction | D18: SODIUM CYANIDE | E18: NA | H18: 250 | J18: =J17+H18-I18 -> 1450 | L18: 1.16 | M18: =H18/L18 -> 215.51724 | O18: =O17+M18-N18 -> 1415.5172 | P18: 30 | Q18: =P18/60 -> 0.5 | R18: 600-650mmHg | S18: Vacuum | T18: 25-30 deg C | U18: CW / CHW | X18: Agitator Dia. | Y18: 1100 mm | AB18: MOC | AC18: Graphite
B19: 3 | C19: Mixing for 1 hr | J19: =J18+H19-I19 -> 1450 | O19: =O18+M19-N19 -> 1415.5172 | P19: 60 | Q19: =P19/60 -> 1 | R19: ATM | T19: 25 - 30 Deg. C | U19: CW / CHW | X19: Motor Power | Y19: 15 HP | AB19: Type | AC19: Cylindrical
B20: Total | D20: - | E20: - | F20: - | H20: =SUM(H17:H19) -> 1450 | I20: =SUM(I17:I19) -> 0 | J20: =H20-I20 -> 1450 | L20: - | M20: =SUM(M17:M19) -> 1415.5172 | N20: =SUM(N17:N19) -> 0 | O20: =M20-N20 -> 1415.5172 | P20: =SUM(P17:P19) -> 150 | Q20: =SUM(Q17:Q19) -> 2.5 | R20: - | S20: - | T20: - | U20: - | X20: Mechanical Seal / Glad Packing | Y20: Single
B21: 10 KL SSR (R-1310 / R-1311 / R-1312 / R-1313 / R-1314 / R-1315 / R-1316 / R-1317) Reactor Qty : 8 Nos | X21: Reactor Diameter | Y21: 2100 mm
B22: 1 | C22: Charge 3500 kg hexane at RT with respective day tank (DT-XXXX). | D22: HEXANE | E22: NA | H22: 3500 | J22: =H22-I22 -> 3500 | L22: 0.65 | M22: =H22/L22 -> 5384.6154 | O22: =M22-N22 -> 5384.6154 | P22: 120 | Q22: =P22/60 -> 2 | R22: ATM | T22: 25-30 deg C | U22: CW | X22: Reactor Drawing | Y22: HLE
B23: =1+B22 -> 2 | C23: Mixture feeding from Cyanide Reactor. | D23: Mixer | E23: NA | H23: 1200 | J23: =J22+H23-I23 -> 4700 | L23: 1 | M23: =H23/L23 -> 1200 | O23: =O22+M23-N23 -> 6584.6154 | P23: 60 | Q23: =P23/60 -> 1 | R23: ATM | T23: 25-30 deg C | U23: CW | V23: BCT is consider for mixture feeding | X23: Agitator Type | Y23: Anchor
E24: NA | H24: 250 | J24: =J23+H24-I24 -> 4950 | L24: 1.16 | M24: =H24/L24 -> 215.51724 | O24: =O23+M24-N24 -> 6800.1326 | P24: 30 | Q24: =P24/60 -> 0.5
B25: =1+B23 -> 3 | C25: Charge SC | D25: SC | E25: NA | H25: 21 | J25: =J24+H25-I25 -> 4971 | L25: 2.5 | M25: =H25/L25 -> 8.4 | O25: =O24+M25-N25 -> 6808.5326 | P25: 30 | Q25: =P25/60 -> 0.5 | R25: 600-650mmHg | S25: Vacuum | T25: 25-30 deg C | U25: CW
B26: =1+B25 -> 4 | C26: Charge Cat-2 | D26: Cat - 2 | E26: NA | H26: 30 | J26: =J25+H26-I26 -> 5001 | L26: 1.15 | M26: =H26/L26 -> 26.086957 | O26: =O25+M26-N26 -> 6834.6196 | P26: 30 | Q26: =P26/60 -> 0.5 | R26: 600-650mmHg | S26: Vacuum | T26: 25-30 deg C | U26: CW
B27: =1+B26 -> 5 | C27: Close man-hole and apply chilled water and maintain 24 deg C temperature(start stirre) | J27: =J26+H27-I27 -> 5001 | O27: =O26+M27-N27 -> 6834.6196 | P27: 120 | Q27: =P27/60 -> 2 | R27: ATM | T27: 24 deg C | U27: CHW
B28: =1+B27 -> 6 | C28: Slow addition of prepared mixture in 4 hr at 20-25 degree c | D28: Mixer | E28: NA | H28: =J12 -> 3300 | J28: =J27+H28-I28 -> 8301 | L28: 1.2 | M28: =H28/L28 -> 2750 | O28: =O27+M28-N28 -> 9584.6196 | P28: 300 | Q28: =P28/60 -> 5 | R28: ATM | T28: 24 deg C | U28: CHW
B29: =1+B28 -> 7 | C29: Maintain the reaction mass for 1 hr @ 20-25 degree c | J29: =J28+H29-I29 -> 8301 | O29: =O28+M29-N29 -> 9584.6196 | P29: 120 | Q29: =P29/60 -> 2 | R29: ATM | T29: 24 deg C | U29: CHW
B30: =1+B29 -> 8 | C30: Send sample to QC | J30: =J29+H30-I30 -> 8301 | O30: =O29+M30-N30 -> 9584.6196 | P30: 120 | Q30: =P30/60 -> 2 | R30: ATM | T30: 24 deg C | U30: CHW/CW | X30: Equipment Name | Y30: R-1310 to R-1317
B31: =1+B30 -> 9 | C31: increase to 40 degree c and then settle for 1 hr | J31: =J30+H31-I31 -> 8301 | O31: =O30+M31-N31 -> 9584.6196 | P31: 120 | Q31: =P31/60 -> 2 | R31: ATM | T31: 40 deg C | U31: Steam | X31: Process Step | Y31: REACTION
B32: =1+B31 -> 10 | C32: Layer separation and Aq. Cyanide layer to 10 KL SSR ( R-1215 / R-1216) reactor by vacuum for hypo treatment | I32: 2000 | J32: =J31+H32-I32 -> 6301 | L32: 1 | N32: =I32/L32 -> 2000 | O32: =O31+M32-N32 -> 7584.6196 | P32: 120 | Q32: =P32/60 -> 2 | R32: ATM | T32: 35 -40 deg C | U32: Steam/CW | X32: Batch Cycle Time | Y32: =Q72 -> 171
B33: =1+B32 -> 11 | C33: Add 500kg water to the reactor and stire for 20 min | D33: WATER | E33: 18 | H33: 500 | J33: =J32+H33-I33 -> 6801 | L33: 1 | M33: =H33/L33 -> 500 | O33: =O32+M33-N33 -> 8084.6196 | P33: 90 | Q33: =P33/60 -> 1.5 | R33: ATM | T33: 35- 40 deg c | U33: Steam/CW | X33: MOC | Y33: SS316
B34: =1+B33 -> 12 | C34: Settling for 30 min | J34: =J33+H34-I34 -> 6801 | O34: =O33+M34-N34 -> 8084.6196 | P34: 30 | Q34: =P34/60 -> 0.5 | R34: ATM | T34: =T33 -> 35- 40 deg c | U34: Steam/CW | X34: Nature | Y34: Basic & Acidic
B35: =1+B34 -> 13 | C35: Separate Aq. Layer to (R-1215 / R-1216) | I35: 600 | J35: =J34+H35-I35 -> 6201 | L35: 0.9 | N35: =I35/L35 -> 666.66667 | O35: =O34+M35-N35 -> 7417.9529 | P35: 60 | Q35: =P35/60 -> 1 | R35: ATM | T35: =T34 -> 35- 40 deg c | U35: Steam/CW | X35: Reactor Volume | Y35: 10 KL
B36: =1+B35 -> 14 | C36: Add 250kg hypo and 1000kg water stirr for 30 min and settling | D36: HYPO | E36: NA | H36: 1250 | J36: =J35+H36-I36 -> 7451 | L36: 1.05 | M36: =H36/L36 -> 1190.4762 | O36: =O35+M36-N36 -> 8608.4291 | P36: 90 | Q36: =P36/60 -> 1.5 | R36: ATM | T36: =T35 -> 35- 40 deg c | U36: NR | X36: Pressure | Y36: FV TO ATM
B37: =1+B36 -> 15 | C37: Separate Aq. Layer and send to ETP | I37: 1300 | J37: =J36+H37-I37 -> 6151 | L37: 0.9 | N37: =I37/L37 -> 1444.4444 | O37: =O36+M37-N37 -> 7163.9847 | P37: 90 | Q37: =P37/60 -> 1.5 | R37: ATM | T37: =T36 -> 35- 40 deg c | U37: NR | X37: Temperature | Y37: MINUS 10 TO 85 Deg. C max.
B38: =1+B37 -> 16 | C38: Add 1500kg water and agitate for 20 min and settling for 30 min | D38: WATER | E38: 18 | H38: 1500 | J38: =J37+H38-I38 -> 7651 | L38: 1 | M38: =H38/L38 -> 1500 | O38: =O37+M38-N38 -> 8663.9847 | P38: 90 | Q38: =P38/60 -> 1.5 | R38: ATM | T38: =T37 -> 35- 40 deg c | U38: NR | X38: RPM | Y38: 92
B39: =1+B38 -> 17 | C39: Lower Aq. Layer send to ETP | I39: 1700 | J39: =J38+H39-I39 -> 5951 | L39: 0.9 | N39: =I39/L39 -> 1888.8889 | O39: =O38+M39-N39 -> 6775.0958 | P39: 90 | Q39: =P39/60 -> 1.5 | R39: ATM | T39: =T38 -> 35- 40 deg c | U39: NR | X39: Agitator Dia. | Y39: 975 mm
B40: =1+B39 -> 18 | C40: Charge 10kg Acetic Acid(98%) from Glass Pot (GP-1306 / GP-1307 / GP-1308 / GP-1309 / GP-1310 / GP-1311 / GP-1312 / GP-1313) & 1500kg water and stire for for 30 min | D40: ACETIC ACID | E40: NA | H40: 1510 | J40: =J39+H40-I40 -> 7461 | L40: 1 | M40: =H40/L40 -> 1510 | O40: =O39+M40-N40 -> 8285.0958 | P40: 90 | Q40: =P40/60 -> 1.5 | R40: ATM | T40: =T39 -> 35- 40 deg c | U40: NR | X40: Motor Power | Y40: 10 HP
B41: =1+B40 -> 19 | C41: Separate lower Aq. Layer and send to ETP | I41: 1610 | J41: =J40+H41-I41 -> 5851 | L41: 0.9 | N41: =I41/L41 -> 1788.8889 | O41: =O40+M41-N41 -> 6496.2069 | P41: 90 | Q41: =P41/60 -> 1.5 | R41: ATM | T41: 25-30 deg C | U41: NR | X41: Mechanical Seal / Glad Packing | Y41: Double
...

Sheet BFD
B2: INPUT | E2: KG | M2: KG | N2: OUTPUT
B4: 6.3 KL GLR
G6: Reactor - Mixing Capacity : 6.3 KL Tag No : PM-1402 / PM-XXXX MOC : MSGL BCT : 16.5 Hrs
B8: Hexane | E8: =xx!H10 -> 1200
B9: MPBD | E9: =xx!H11 -> 875
B10: IN-1 | E10: =xx!H12 -> 1225
J16: Reaction Mass | L16: =xx!J15 -> 3300
B17: 10 KL SSR
G19: Reactor - Reaction Layer Separation & Distillation Capacity : 10 KL Tag No : R-1310 / R-1311 / R-1312 / R-1313 / R-1314 / R-1315 / R-1316 / R-1317 MOC : SS316 BCT : 171 Hrs
B20: Hexane | E20: =xx!H22 -> 3500
B21: Water from Cyanide Reactor (R-1402) | E21: =xx!H23 -> 1200 | M21: =xx!I42 -> 2000 | N21: Recover Solvent - ATM
B22: Sodium Cyanide from (R-1402) | E22: =xx!H24 -> 250 | M22: =xx!I44 -> 1100 | N22: Recover Solvent - Vacuum
B23: SC | E23: =xx!H25 -> 21
B24: Cat-2 | E24: =xx!H26 -> 30
B25: 1st - Water Wash | E25: =xx!H33 -> 500
B26: 2nd - Water Wash Hypo + Water | E26: =xx!H36 -> 1250
B27: 3rd - Water Wash | E27: =xx!H38 -> 1500
B28: 4th Water Wash + Acetic Acid | E28: =xx!H40 -> 1510
B29: IPA | E29: =xx!H45 -> 2000 | M29: =xx!I70 -> 1767 | N29: 10th Water Wash Aq. Layer - ETP
B30: Base - Liquid | E30: =xx!H47 -> 85 | M30: =xx!I68 -> 1800 | N30: 9th Water Wash Aq. Layer - ETP
B31: CFG-2 Powder | E31: =xx!H48 -> 5 | M31: =xx!I66 -> 1800 | N31: 8th Water Wash Aq. Layer - ETP
B32: 1st Lot Addition - HCL + Water | E32: =xx!H53 -> 260 | M32: =xx!I64 -> 1800 | N32: 6th Water Wash Aq. Layer - ETP
B33: 2nd Lot Addition - HCL + Water | E33: =xx!H54 -> 260 | M33: =xx!I62 -> 1800 | N33: 5th Water Wash Aq. Layer - ETP
B34: Hexane | E34: =xx!H55 -> 2800 | M34: =xx!I61 -> 800 | N34: 2nd Aq. Layer of IPA + Water
B35: 3rd Lot Addition - HCL + Water | E35: =xx!H56 -> 260 | M35: =xx!I59 -> 2500 | N35: 1st Aq. Layer of IPA + Water
B36: 5th - Water Wash | E36: =xx!H60 -> 500 | M36: =xx!I41 -> 1610 | N36: 4thWater Wash Aq. Layer - ETP
B37: 6th - Water Wash | E37: =xx!H62 -> 1500 | M37: =xx!I39 -> 1700 | N37: 3rd Water Wash Aq. Layer - ETP
B38: 7th - Water Wash | E38: =xx!H63 -> 1500 | M38: =xx!I37 -> 1300 | N38: 2nd Water Wash Aq. Layer - ETP
B39: 8th Water Wash | E39: =xx!H65 -> 1500 | M39: =xx!I35 -> 600 | N39: 1st Water Wash Aq. Layer
B40: 9th Water Wash + SBC | E40: =xx!H67 -> 1503 | M40: =xx!I32 -> 2000 | N40: Main Aq. Cyanide Layer
B41: 10th Water Wash + Acetic Acid | E41: =xx!H69 -> 1510
M45: =xx!I71 -> 4167 | N45: Liquid Mass for Crystallization
B48: Total Input | E48: =SUM(E6:E47) -> 26744 | M48: =SUM(M6:M47) -> 26744 | N48: Total Output
B51: 6.3 KL GLR / Crystallization
G54: Reactor - Crystallization Capacity : 6.3 KL Tag No : R-1212/ R-1213/ R-1214 MOC : GLR BCT : 31.3 Hrs
B55: Liuid Mass | E55: =xx!H74 -> 4167
B57: CFG-2 Powder | E57: =xx!H76 -> 5
J61: Reaction Mass | L61: =xx!I79 -> 4172
B63: 5 KL SS / ANFD
G65: ANFD - Filtration + Drying Capacity : 5 KL Tag No : ANFD-1104 / ANFD-1105 / ANFD-1106 / ANFD-1107 MOC : SS316 BCT : 3.3 Hrs
...

Sheet Enthalpy Balance
K2: Project No.
K3: Document No.
K4: Issued for
K5: Prepared By
B6: Date | K6: Checked By
B7: Rev. | K7: Approved By | M7: Location
B8: 6.3 KL GLR / Pre Mixer
B9: Step No. | C9: Reactor Use | D9: Reactor Capacity (KL) | E9: Status | F9: Avg. Density ( Kg/m3) | G9: Reaction Temp (Deg.C) | H9: Consider Vapor flow rate of mass | I9: Solvent used for reflux | J9: Reflux cycle ( no of times ) | K9: Solvent % in batch | L9: Chilling time (hrs) | M9: Chilling water Flow Rate (m3/hr)
B10: 1 to 3 | C10: GLR | D10: 6.3 | E10: Working | F10: - | G10: 20 | H10: - | I10: - | J10: - | K10: - | L10: =H21 -> 0.83975273 | M10: =L15 -> 14.2
C12: Chilling Water Requirement | G12: Time Required for Chilling | K12: Chilling Water Supply
C14: Process Fluid Volume | D14: =D10 -> 6.3 | E14: m3 | G14: Utility Inlet Temperature | H14: 7 | I14: °C | K14: Heat Load | L14: =D22/H24 -> 46200 | M14: kcal/hr
C15: Average Density of Process Fluid | D15: - | E15: kg/m3 | G15: Specifc Heat of Process Liquid | H15: =D17 -> 0.7 | I15: kcal/kg °C | K15: Min. Req. Chilling Flowrate | L15: =IF(L14/5/1000<14.2,14.2,L14/5/1000) -> 14.2 | M15: m3/hr
C16: Mass of Reaction Material | D16: =xx!J12 -> 3300 | E16: kg | G16: Process Liquid Intial Temperature | H16: =D19 -> 30 | I16: °C | K16: Calculated Flow rate | L16: =L14/5/1000 -> 9.24
C17: Average Specific Heat Considered | D17: 0.7 | E17: kcal/kg °C | G17: Process Liquid Final Temperature | H17: =D20 -> 15 | I17: °C
C18: Latent Heat of Vaporization of Solvent | D18: - | E18: kcal/kg | G18: Effective Heat Transfer Area | H18: =D21 -> 16.6 | I18: m2
C19: Initial Temperature | D19: 30 | E19: °C | G19: Overcall Heat Transfer Coefficient | H19: 175 | I19: kcal/hr*m2*°C
C20: Final Temperature | D20: 15 | E20: °C
C21: Approx. Heat Transfer Area of Reactor | D21: 16.6 | E21: m2 | G21: Time Calculated | H21: =((D16*D17)/(H18*H19))*(LN((H16-H14)/(H17-H14))) -> 0.83975273 | I21: hr
C22: Thermodynamic Heat | D22: =D16*D17*(D19-D20) -> 34650 | E22: kcal | G22: We have assume the Chilling time (t)
G23: Chilling Time (t) | H23: 45 | I23: min
G24: Chilling Time (t) | H24: =H23/60 -> 0.75 | I24: hr
B25: Step No. | C25: Reactor Use | D25: Reactor Capacity (KL) | E25: Status | F25: Avg. Density ( Kg/m3) | G25: Reaction Temp (Deg.C) | H25: Consider Vapor flow rate of mass | I25: Solvent used for reflux | J25: Reflux cycle ( no of times ) | K25: Solvent % in batch | L25: Chilling + Brine time (hrs) | M25: Chilling water Flow Rate (m3/hr)
B26: 4 & 5 | C26: GLR | D26: 6.3 | E26: Working | F26: - | G26: 8 | H26: - | I26: - | J26: - | K26: - | L26: =H42 -> 0.33333333 | M26: =#REF! -> #REF!
C30: Brine Requirement | G30: Time Required for Brine | K30: Brine Supply
C32: Process Fluid Volume | D32: =D26 -> 6.3 | E32: m3 | G32: Utility Inlet Temperature | H32: -15 | I32: °C | K32: Heat Load | L32: =D40/H42 -> 48510 | M32: kcal/hr
C33: Average Density of Process Fluid | D33: - | E33: kg/m3 | G33: Specifc Heat of Process Liquid | H33: =D35 -> 0.7 | I33: kcal/kg °C | K33: Min. Req. Brine Flowrate | L33: =IF(L32/5/1000<14.2,14.2,L32/5/1000) -> 14.2 | M33: m3/hr
C34: Mass of Reaction Material | D34: =D16 -> 3300 | E34: kg | G34: Process Liquid Intial Temperature | H34: =D37 -> 15 | I34: °C | K34: Calculated Flow rate | L34: =L32/5/1000 -> 9.702
C35: Average Specific Heat Considered | D35: 0.7 | E35: kcal/kg °C | G35: Process Liquid Final Temperature | H35: =D38 -> 8 | I35: °C
C36: Latent Heat of Vaporization of Solvent | D36: - | E36: kcal/kg | G36: Effective Heat Transfer Area | H36: =D39 -> 16.6 | I36: m2
C37: Initial Temperature | D37: 15 | E37: °C | G37: Overcall Heat Transfer Coefficient | H37: 150 | I37: kcal/hr*m2*°C
C38: Final Temperature | D38: 8 | E38: °C
C39: Approx. Heat Transfer Area of Reactor | D39: 16.6 | E39: m2 | G39: Time Calculated | H39: =((D34*D35)/(H36*H37))*(LN((H34)-(H32))/((H35)-(H32))) -> 0.13718816 | I39: hr
C40: Thermodynamic Heat | D40: =D34*D35*(D37-D38) -> 16170 | E40: kcal | G40: We have assume the Chilling time (t)
G41: Chilling Time (t) | H41: 20 | I41: min
G42: Chilling Time (t) | H42: =H41/60 -> 0.33333333 | I42: hr
B45: 3 KL SSR / Cyanide Reactor
B46: Step No. | C46: Reactor Use | D46: Reactor Capacity (KL) | E46: Status | F46: Avg. Density ( Kg/m3) | G46: Reaction Temp (Deg.C) | H46: Consider Vapor flow rate of mass | I46: Solvent used for reflux | J46: Reflux cycle ( no of times ) | K46: Solvent % in batch | L46: Chilling time (hrs) | M46: Chilling Water Flow Rate (m3/hr)
B47: 1 to 3 | C47: SSR | D47: 3 | E47: Working | F47: - | G47: 25 | H47: - | I47: - | J47: - | K47: - | L47: =H61 -> 0.33333333 | M47: =L52 -> 14.2
C49: Chilling Water Requirement | G49: Time Required for Chilling | K49: Chilling Water Supply
C51: Process Fluid Volume | D51: =D47 -> 3 | E51: m3 | G51: Utility Inlet Temperature | H51: 7 | I51: °C | K51: Heat Load | L51: =D59/H61 -> 15225 | M51: kcal/hr
...

Sheet Utility Calculation
R1: Project No.
R2: Document No.
R3: Issued for
R4: Prepared By
B5: Date | R5: Checked By
B6: Rev. | R6: Approved By | U6: Location
B8: Sr. No. | C8: Equipment | E8: Capacity (KL) | F8: MOC | G8: Step No. | H8: Utility Time (hr) | I8: Steam (Kg/hr) | J8: Total Steam (Kg) | K8: Cooling Water (m3/hr) | L8: Total Cooling Water (m3) | M8: Chilling Water (m3/hr) | N8: Total Chilling Water (m3) | O8: Brine (m3/hr) | P8: Total Brine (m3) | Q8: Hot Water (m3/hr) | R8: Total Hot Water (m3) | S8: Vacuum (mmHg) | T8: Nitrogen (m3/hr) | U8: Total Nitrogen (m3) | V8: Compressed Air (m3/hr) | W8: Total Compressed Air (m3)
C9: Tag No. | D9: Description
B10: 1 | C10: AV-XXXX | D10: Hexane Charging Vessel | E10: 10 KL | F10: HDPE | G10: 1 | H10: 0.8 | I10: - | J10: - | K10: - | L10: - | M10: - | N10: - | O10: - | P10: - | Q10: - | R10: - | S10: - | T10: - | U10: - | V10: - | W10: -
B11: 2 | C11: PM-1441 | D11: Pre-Mixer | E11: 6.3 KL | F11: MSGL | G11: 1-3 | H11: 2 | I11: - | J11: - | K11: - | L11: - | M11: 3.5 | N11: =M11*H11 -> 7 | O11: - | P11: - | Q11: - | R11: - | S11: 650 | T11: - | U11: - | V11: - | W11: -
G12: 4-5 | H12: 2 | I12: - | J12: - | K12: - | L12: - | M12: - | N12: - | O12: 1.84 | P12: =O12*H12 -> 3.68 | Q12: - | R12: - | U12: - | V12: - | W12: -
B13: 3 | C13: R-1441 | D13: Cyanide Reactor | E13: 3 KL | F13: SS316 | G13: 1-3 | H13: 1 | I13: - | J13: - | K13: - | L13: - | M13: 1.02 | N13: =M13*H13 -> 1.02 | O13: - | P13: - | Q13: - | R13: - | S13: 650 | U13: - | V13: - | W13: -
B14: 4 | C14: R-1341/R-1342/R-1343 | D14: Reactor | E14: 10 KL | F14: SS316 | G14: 1-5 | H14: 3 | I14: - | J14: - | K14: - | L14: - | M14: 1.4 | N14: =M14*H14 -> 4.2 | O14: - | P14: - | Q14: - | R14: - | S14: 650 | T14: - | U14: - | V14: - | W14: -
G15: 6-8 | H15: 5 | I15: - | J15: - | K15: - | L15: - | M15: 0.55 | N15: =M15*H15 -> 2.75 | O15: - | P15: - | Q15: - | R15: - | S15: - | T15: - | U15: - | V15: - | W15: -
G16: 9 | H16: 2 | I16: 91.15 | J16: =I16*H16 -> 182.3 | K16: - | L16: - | M16: - | N16: - | O16: - | P16: - | Q16: - | R16: - | S16: - | T16: - | U16: - | V16: - | W16: -
G17: 11 | H17: 1 | I17: 6.86 | J17: =I17*H17 -> 6.86 | K17: - | L17: - | M17: - | N17: - | O17: - | P17: - | Q17: - | R17: - | S17: - | T17: - | U17: - | V17: - | W17: -
G18: 14 | H18: 0.5 | I18: 34.31 | J18: =I18*H18 -> 17.155 | K18: - | L18: - | M18: - | N18: - | O18: - | P18: - | Q18: - | R18: - | S18: - | T18: - | U18: - | V18: - | W18: -
G19: 16 | H19: 0.7 | I19: 30.88 | J19: =I19*H19 -> 21.616 | K19: - | L19: - | M19: 2.08 | N19: =M19*H19 -> 1.456 | O19: - | P19: - | Q19: - | R19: - | S19: - | T19: - | U19: - | V19: - | W19: -
G20: 18 | H20: 1 | I20: 20.73 | J20: =I20*H20 -> 20.73 | K20: - | L20: - | M20: - | N20: - | O20: - | P20: - | Q20: - | R20: - | S20: - | T20: - | U20: - | V20: - | W20: -
G21: 20 | H21: 6 | I21: 105.83 | J21: =I21*H21 -> 634.98 | K21: - | L21: - | M21: - | N21: - | O21: - | P21: - | Q21: - | R21: - | S21: - | T21: - | U21: - | V21: - | W21: -
G22: 22 | H22: 5 | I22: 34.5 | J22: =I22*H22 -> 172.5 | K22: - | L22: - | M22: - | N22: - | O22: - | P22: - | Q22: - | R22: - | S22: 700 | U22: - | V22: - | W22: -
D23: IPA | G23: 23-1 | H23: 1 | I23: - | J23: - | K23: 9.63 | L23: =K23*H23 -> 9.63 | O23: - | P23: - | Q23: - | R23: - | S23: - | T23: - | U23: - | V23: - | W23: -
G24: 23-2 | H24: 0.75 | I24: - | J24: - | K24: - | L24: - | M24: 5.14 | N24: =M24*H24 -> 3.855 | O24: - | P24: - | Q24: - | R24: - | S24: - | T24: - | U24: - | V24: - | W24: -
G25: 24-26 | H25: 0.75 | I25: - | J25: - | K25: - | L25: - | M25: 13.55 | N25: =M25*H25 -> 10.1625 | O25: - | P25: - | Q25: - | R25: - | S25: 600 | U25: - | V25: - | W25: -
H26: 1.25 | I26: - | J26: - | K26: - | L26: - | M26: - | N26: - | O26: 6.16 | P26: =O26*H26 -> 7.7 | Q26: - | R26: - | S26: - | T26: - | U26: - | V26: - | W26: -
G27: 27-29 | H27: 6 | I27: - | J27: - | K27: - | L27: - | M27: - | N27: - | O27: 1.93 | P27: =O27*H27 -> 11.58 | Q27: - | R27: - | S27: - | T27: - | U27: - | V27: - | W27: -
D28: HCl Charging Vessel | G28: 31-32 | H28: 2 | I28: - | J28: - | K28: - | L28: - | M28: - | N28: - | O28: 1.65 | P28: =O28*H28 -> 3.3 | Q28: - | R28: - | S28: - | T28: - | U28: - | V28: - | W28: -
G29: 33 | H29: 2 | I29: - | J29: - | K29: - | L29: - | M29: - | N29: - | O29: 8.91 | P29: =O29*H29 -> 17.82 | Q29: - | R29: - | S29: - | T29: - | U29: - | V29: - | W29: -
G30: 34 | H30: 1 | I30: - | J30: - | K30: - | L30: - | M30: - | N30: - | O30: 1.65 | P30: =O30*H30 -> 1.65 | Q30: - | R30: - | S30: - | T30: - | U30: - | V30: - | W30: -
G31: 35-1 | H31: 1 | I31: - | J31: - | K31: - | L31: - | M31: 15.33 | N31: =M31*H31 -> 15.33 | O31: - | P31: - | Q31: - | R31: - | S31: - | T31: - | U31: - | V31: - | W31: -
G32: 35-2 | H32: 1.5 | I32: - | J32: - | K32: 16.51 | L32: =K32*H32 -> 24.765 | M32: - | N32: - | O32: - | P32: - | Q32: - | R32: - | S32: - | T32: - | U32: - | V32: - | W32: -
G33: 35-3 | H33: 0.5 | I33: 208 | J33: =I33*H33 -> 104 | K33: - | L33: - | M33: - | N33: - | O33: - | P33: - | Q33: - | R33: - | S33: - | T33: - | U33: - | V33: - | W33: -
G34: 38 | H34: 1 | I34: - | J34: - | K34: - | L34: - | M34: 0.56 | N34: =M34*H34 -> 0.56 | O34: - | P34: - | Q34: - | R34: - | S34: - | T34: - | U34: - | V34: - | W34: -
G35: 40 | H35: 0.67 | I35: - | J35: - | K35: - | L35: - | M35: 1.58 | N35: =M35*H35 -> 1.0586 | O35: - | P35: - | Q35: - | R35: - | S35: - | T35: - | U35: - | V35: - | W35: -
G36: 41 | H36: 1 | I36: - | J36: - | K36: - | L36: - | M36: 1.05 | N36: =M36*H36 -> 1.05 | O36: - | P36: - | Q36: - | R36: - | S36: - | T36: - | U36: - | V36: - | W36: -
G37: 42 | H37: 1 | I37: - | J37: - | K37: - | L37: - | M37: - | N37: - | O37: - | P37: - | Q37: - | R37: - | S37: - | T37: - | U37: - | V37: - | W37: -
G38: 43 | H38: 1 | I38: - | J38: - | K38: - | L38: - | M38: 1.05 | N38: =M38*H38 -> 1.05 | O38: - | P38: - | Q38: - | R38: - | S38: - | T38: - | U38: - | V38: - | W38: -
G39: 44 | H39: 0.5 | I39: - | J39: - | K39: - | L39: - | M39: - | N39: - | O39: - | P39: - | Q39: - | R39: - | S39: - | T39: - | U39: - | V39: - | W39: -
G40: 45 | H40: 1 | I40: - | J40: - | K40: - | L40: - | M40: 1.05 | N40: =M40*H40 -> 1.05 | O40: - | P40: - | Q40: - | R40: - | S40: - | T40: - | U40: - | V40: - | W40: -
G41: 47 | H41: 1 | I41: - | J41: - | K41: - | L41: - | M41: 1.06 | N41: =M41*H41 -> 1.06 | O41: - | P41: - | Q41: - | R41: - | S41: - | T41: - | U41: - | V41: - | W41: -
...

Sheet RM Data
B3: RM | C3: Chemical Name | D3: CAS Number | E3: Molecular Formula | F3: State of Chemical | G3: Mol Wt. (Kg/Kmol) | H3: Density (Kg/m3) | I3: Specific Gravity | J3: MP (°C) | K3: BP (°C) | L3: Flash point (°C) | M3: Vapor Density (kg/m3) | N3: Auto Ignition Temperature(°C) | O3: Cp (KJ/Kg K) | P3: Cp (Kcal/Kg K) | Q3: ∆Hvap (KJ/Kg) | R3: ∆Hf (KJ/mol) | S3: PH | T3: Solubility in Water | U3: Viscocity (cP) | V3: Vapour Pressure | W3: Corrosivity
B4: HEXANE | C4: - | D4: - | E4: - | F4: liquid | G4: - | H4: 661 | I4: 0.659 | J4: -95 | K4: 69 | L4: -22 | M4: 2.97 | N4: 223 | O4: NA | P4: NA | Q4: NA | R4: NA | S4: NA | T4: Insoluble | U4: 0.31 | V4: 160mbar | W4: NO
B5: MPBD | C5: - | D5: - | E5: - | F5: liquid | G5: - | H5: NA | I5: 1.147 | J5: 13 | K5: NA | L5: >112 | M5: 7.8 | N5: NA | O5: NA | P5: NA | Q5: NA | R5: NA | S5: NA | T5: NA | U5: NA | V5: NA | W5: No
B6: IN-1 | C6: - | D6: - | E6: - | F6: Liquid | G6: - | H6: 1.44 gm/cc | I6: NA | J6: NA | K6: 240 | L6: 92.2 | M6: NA | N6: NA | O6: NA | P6: NA | Q6: 46.55 | R6: NA | S6: NA | T6: NA | U6: NA | V6: NA | W6: Yes
B7: WATER | C7: - | D7: - | E7: - | F7: Liquid | G7: - | H7: 998 | I7: 1 | J7: 0 | K7: 100 | L7: NA | M7: NA | N7: NA | O7: NA | P7: NA | Q7: NA | R7: NA | S7: 6-7 | T7: NA | U7: NA | V7: NA | W7: No
B8: SODIUM CYANIDE | C8: - | D8: - | E8: - | F8: Solid | G8: - | H8: NA | I8: NA | J8: 562 | K8: 1497 | L8: NA | M8: NA | N8: NA | O8: NA | P8: NA | Q8: NA | R8: NA | S8: 11-12 | T8: NA | U8: NA | V8: 1hPa at 817°C | W8: NO
B9: SC | C9: - | D9: - | E9: - | F9: Solid | G9: - | H9: NA | I9: 2.53 | J9: 854 | K9: 1600 | L9: NA | M9: NA | N9: NA | O9: NA | P9: NA | Q9: NA | R9: NA | S9: 11.3 | T9: Partially Soluble | U9: NA | V9: NA | W9: NO
B10: MIXER | C10: - | D10: - | E10: - | F10: liquid | G10: - | H10: NA | I10: NA | J10: NA | K10: NA | L10: NA | M10: NA | N10: NA | O10: NA | P10: NA | Q10: NA | R10: NA | S10: NA | T10: NA | U10: NA | V10: NA | W10: Yes
B11: CAT-2 | C11: - | D11: - | E11: - | F11: Solid | G11: - | H11: NA | I11: 1.15 | J11: 100-104 | K11: NA | L11: NA | M11: NA | N11: NA | O11: NA | P11: NA | Q11: NA | R11: NA | S11: NA | T11: 0.01 | U11: NA | V11: NA | W11: No
B12: HYPO | C12: - | D12: - | E12: - | F12: liquid | G12: - | H12: NA | I12: 1.1 | J12: NA | K12: NA | L12: NA | M12: 2.57 | N12: NA | O12: NA | P12: NA | Q12: NA | R12: NA | S12: 12.52 | T12: Soluble | U12: NA | V12: NA | W12: No
B13: ACETIC ACID | C13: - | D13: - | E13: - | F13: liquid | G13: - | H13: 1051 | I13: 1.048 | J13: 16-16.5 | K13: 117-118 | L13: 40 | M13: 2.1 | N13: 427 | O13: NA | P13: NA | Q13: NA | R13: NA | S13: <2.5 | T13: Soluble | U13: 1.53mPa.s | V13: 1.52kPa | W13: No
B14: IPA | C14: - | D14: - | E14: - | F14: liquid | G14: - | H14: 786 | I14: 0.785 | J14: -89.5 | K14: 81-83 | L14: 12 | M14: 2.1 | N14: 425 | O14: NA | P14: NA | Q14: NA | R14: NA | S14: 7 | T14: miscible | U14: 2.27mPa.s | V14: 43mmhg | W14: No
B15: CFG-2 POWDER | C15: - | D15: - | E15: - | F15: NA | G15: - | H15: NA | I15: NA | J15: NA | K15: NA | L15: NA | M15: NA | N15: NA | O15: NA | P15: NA | Q15: NA | R15: NA | S15: NA | T15: NA | U15: NA | V15: NA | W15: No
B16: HCL | C16: - | D16: - | E16: - | F16: Liquid | G16: - | H16: 1180 | I16: 1.18 | J16: 35 | K16: 57 | L16: NA | M16: 1.27 | N16: NA | O16: NA | P16: NA | Q16: NA | R16: NA | S16: 1 | T16: miscible | U16: 1.8mPa.s | V16: 125 | W16: Yes
B17: BASE - LIQUID | C17: - | D17: - | E17: - | F17: Liquid | G17: - | H17: 707 | I17: 0.71 | J17: -50 | K17: 55 | L17: -23 | M17: NA | N17: 312 | O17: NA | P17: NA | Q17: NA | R17: NA | S17: 12 | T17: Soluble | U17: NA | V17: 250 | W17: No
B18: SBC | C18: - | D18: - | E18: - | F18: Solid | G18: - | H18: NA | I18: NA | J18: 270 | K18: NA | L18: NA | M18: NA | N18: NA | O18: NA | P18: NA | Q18: NA | R18: NA | S18: 8.3 | T18: Slightly soluble | U18: NA | V18: NA | W18: No
B19: CAUSTIC | C19: - | D19: - | E19: - | F19: Solid | G19: - | H19: NA | I19: NA | J19: 318 | K19: 1390 | L19: NA | M19: NA | N19: NA | O19: NA | P19: NA | Q19: NA | R19: NA | S19: 14 | T19: NA | U19: NA | V19: 1 mBar | W19: No
